{
 "cells": [
  {
   "cell_type": "code",
   "execution_count": null,
   "id": "uniform-pierce",
   "metadata": {
    "colab": {
     "base_uri": "https://localhost:8080/"
    },
    "collapsed": true,
    "execution": {
     "iopub.execute_input": "2021-05-08T02:07:08.046165Z",
     "iopub.status.busy": "2021-05-08T02:07:08.045367Z",
     "iopub.status.idle": "2021-05-08T02:07:08.051316Z",
     "shell.execute_reply": "2021-05-08T02:07:08.051962Z"
    },
    "executionInfo": {
     "elapsed": 599,
     "status": "ok",
     "timestamp": 1620712740080,
     "user": {
      "displayName": "HHK Mmk",
      "photoUrl": "https://lh3.googleusercontent.com/a-/AOh14Gj9u9VsU8JrrRLuhjNo1_RvBxXqIZIwiILnsBRR=s64",
      "userId": "07317510250984342733"
     },
     "user_tz": -540
    },
    "id": "uniform-pierce",
    "outputId": "933f58ba-5485-4e4e-f65c-a5dbbcf267b3",
    "papermill": {
     "duration": 0.042025,
     "end_time": "2021-05-08T02:07:08.052287",
     "exception": false,
     "start_time": "2021-05-08T02:07:08.010262",
     "status": "completed"
    },
    "tags": []
   },
   "outputs": [
    {
     "name": "stderr",
     "output_type": "stream",
     "text": [
      "ERROR:root:Internal Python error in the inspect module.\n",
      "Below is the traceback from this internal error.\n",
      "\n",
      "ERROR:root:Internal Python error in the inspect module.\n",
      "Below is the traceback from this internal error.\n",
      "\n",
      "ERROR:root:Internal Python error in the inspect module.\n",
      "Below is the traceback from this internal error.\n",
      "\n"
     ]
    },
    {
     "name": "stdout",
     "output_type": "stream",
     "text": [
      "Traceback (most recent call last):\n",
      "  File \"C:\\Users\\admin\\anaconda3\\lib\\site-packages\\IPython\\core\\interactiveshell.py\", line 3444, in run_code\n",
      "    exec(code_obj, self.user_global_ns, self.user_ns)\n",
      "  File \"C:\\Users\\admin\\AppData\\Local\\Temp/ipykernel_19960/1515776653.py\", line 6, in <module>\n",
      "    from tensorflow.keras.models import load_model\n",
      "  File \"C:\\Users\\admin\\anaconda3\\lib\\site-packages\\tensorflow\\__init__.py\", line 101, in <module>\n",
      "    from tensorflow_core import *\n",
      "  File \"C:\\Users\\admin\\anaconda3\\lib\\site-packages\\tensorflow_core\\__init__.py\", line 40, in <module>\n",
      "    from tensorflow.python.tools import module_util as _module_util\n",
      "  File \"C:\\Users\\admin\\anaconda3\\lib\\site-packages\\tensorflow\\__init__.py\", line 50, in __getattr__\n",
      "    module = self._load()\n",
      "  File \"C:\\Users\\admin\\anaconda3\\lib\\site-packages\\tensorflow\\__init__.py\", line 44, in _load\n",
      "    module = _importlib.import_module(self.__name__)\n",
      "  File \"C:\\Users\\admin\\anaconda3\\lib\\importlib\\__init__.py\", line 127, in import_module\n",
      "    return _bootstrap._gcd_import(name[level:], package, level)\n",
      "  File \"C:\\Users\\admin\\anaconda3\\lib\\site-packages\\tensorflow_core\\python\\__init__.py\", line 75, in <module>\n",
      "    from tensorflow.python.framework.framework_lib import *  # pylint: disable=redefined-builtin\n",
      "  File \"C:\\Users\\admin\\anaconda3\\lib\\site-packages\\tensorflow_core\\python\\framework\\framework_lib.py\", line 25, in <module>\n",
      "    from tensorflow.python.framework.ops import Graph\n",
      "  File \"C:\\Users\\admin\\anaconda3\\lib\\site-packages\\tensorflow_core\\python\\framework\\ops.py\", line 46, in <module>\n",
      "    from tensorflow.python.framework import composite_tensor\n",
      "  File \"C:\\Users\\admin\\anaconda3\\lib\\site-packages\\tensorflow_core\\python\\framework\\composite_tensor.py\", line 27, in <module>\n",
      "    from tensorflow.python.util import nest\n",
      "  File \"C:\\Users\\admin\\anaconda3\\lib\\site-packages\\tensorflow_core\\python\\util\\nest.py\", line 40, in <module>\n",
      "    import wrapt as _wrapt\n",
      "ModuleNotFoundError: No module named 'wrapt'\n",
      "\n",
      "During handling of the above exception, another exception occurred:\n",
      "\n",
      "Traceback (most recent call last):\n",
      "  File \"C:\\Users\\admin\\anaconda3\\lib\\site-packages\\IPython\\core\\interactiveshell.py\", line 2064, in showtraceback\n",
      "    stb = value._render_traceback_()\n",
      "AttributeError: 'ModuleNotFoundError' object has no attribute '_render_traceback_'\n",
      "\n",
      "During handling of the above exception, another exception occurred:\n",
      "\n",
      "Traceback (most recent call last):\n",
      "  File \"C:\\Users\\admin\\anaconda3\\lib\\site-packages\\IPython\\core\\ultratb.py\", line 1101, in get_records\n",
      "    return _fixed_getinnerframes(etb, number_of_lines_of_context, tb_offset)\n",
      "  File \"C:\\Users\\admin\\anaconda3\\lib\\site-packages\\IPython\\core\\ultratb.py\", line 248, in wrapped\n",
      "    return f(*args, **kwargs)\n",
      "  File \"C:\\Users\\admin\\anaconda3\\lib\\site-packages\\IPython\\core\\ultratb.py\", line 281, in _fixed_getinnerframes\n",
      "    records = fix_frame_records_filenames(inspect.getinnerframes(etb, context))\n",
      "  File \"C:\\Users\\admin\\anaconda3\\lib\\inspect.py\", line 1495, in getinnerframes\n",
      "    frameinfo = (tb.tb_frame,) + getframeinfo(tb, context)\n",
      "  File \"C:\\Users\\admin\\anaconda3\\lib\\inspect.py\", line 1453, in getframeinfo\n",
      "    filename = getsourcefile(frame) or getfile(frame)\n",
      "  File \"C:\\Users\\admin\\anaconda3\\lib\\inspect.py\", line 696, in getsourcefile\n",
      "    if getattr(getmodule(object, filename), '__loader__', None) is not None:\n",
      "  File \"C:\\Users\\admin\\anaconda3\\lib\\inspect.py\", line 733, in getmodule\n",
      "    if ismodule(module) and hasattr(module, '__file__'):\n",
      "  File \"C:\\Users\\admin\\anaconda3\\lib\\site-packages\\tensorflow\\__init__.py\", line 50, in __getattr__\n",
      "    module = self._load()\n",
      "  File \"C:\\Users\\admin\\anaconda3\\lib\\site-packages\\tensorflow\\__init__.py\", line 44, in _load\n",
      "    module = _importlib.import_module(self.__name__)\n",
      "  File \"C:\\Users\\admin\\anaconda3\\lib\\importlib\\__init__.py\", line 127, in import_module\n",
      "    return _bootstrap._gcd_import(name[level:], package, level)\n",
      "  File \"<frozen importlib._bootstrap>\", line 1006, in _gcd_import\n",
      "  File \"<frozen importlib._bootstrap>\", line 983, in _find_and_load\n",
      "  File \"<frozen importlib._bootstrap>\", line 953, in _find_and_load_unlocked\n",
      "  File \"<frozen importlib._bootstrap>\", line 219, in _call_with_frames_removed\n",
      "  File \"<frozen importlib._bootstrap>\", line 1006, in _gcd_import\n",
      "  File \"<frozen importlib._bootstrap>\", line 983, in _find_and_load\n",
      "  File \"<frozen importlib._bootstrap>\", line 967, in _find_and_load_unlocked\n",
      "  File \"<frozen importlib._bootstrap>\", line 677, in _load_unlocked\n",
      "  File \"<frozen importlib._bootstrap_external>\", line 728, in exec_module\n",
      "  File \"<frozen importlib._bootstrap>\", line 219, in _call_with_frames_removed\n",
      "  File \"C:\\Users\\admin\\anaconda3\\lib\\site-packages\\tensorflow_core\\__init__.py\", line 42, in <module>\n",
      "    from . _api.v2 import audio\n",
      "  File \"C:\\Users\\admin\\anaconda3\\lib\\site-packages\\tensorflow_core\\_api\\v2\\audio\\__init__.py\", line 10, in <module>\n",
      "    from tensorflow.python.ops.gen_audio_ops import decode_wav\n",
      "  File \"C:\\Users\\admin\\anaconda3\\lib\\site-packages\\tensorflow_core\\python\\ops\\gen_audio_ops.py\", line 12, in <module>\n",
      "    from tensorflow.python.eager import execute as _execute\n",
      "  File \"C:\\Users\\admin\\anaconda3\\lib\\site-packages\\tensorflow_core\\python\\eager\\execute.py\", line 28, in <module>\n",
      "    from tensorflow.python.framework import ops\n",
      "  File \"C:\\Users\\admin\\anaconda3\\lib\\site-packages\\tensorflow_core\\python\\framework\\ops.py\", line 46, in <module>\n",
      "    from tensorflow.python.framework import composite_tensor\n",
      "  File \"C:\\Users\\admin\\anaconda3\\lib\\site-packages\\tensorflow_core\\python\\framework\\composite_tensor.py\", line 27, in <module>\n",
      "    from tensorflow.python.util import nest\n",
      "  File \"C:\\Users\\admin\\anaconda3\\lib\\site-packages\\tensorflow_core\\python\\util\\nest.py\", line 40, in <module>\n",
      "    import wrapt as _wrapt\n",
      "ModuleNotFoundError: No module named 'wrapt'\n",
      "Traceback (most recent call last):\n",
      "  File \"C:\\Users\\admin\\anaconda3\\lib\\site-packages\\IPython\\core\\interactiveshell.py\", line 3444, in run_code\n",
      "    exec(code_obj, self.user_global_ns, self.user_ns)\n",
      "  File \"C:\\Users\\admin\\AppData\\Local\\Temp/ipykernel_19960/1515776653.py\", line 6, in <module>\n",
      "    from tensorflow.keras.models import load_model\n",
      "  File \"C:\\Users\\admin\\anaconda3\\lib\\site-packages\\tensorflow\\__init__.py\", line 101, in <module>\n",
      "    from tensorflow_core import *\n",
      "  File \"C:\\Users\\admin\\anaconda3\\lib\\site-packages\\tensorflow_core\\__init__.py\", line 40, in <module>\n",
      "    from tensorflow.python.tools import module_util as _module_util\n",
      "  File \"C:\\Users\\admin\\anaconda3\\lib\\site-packages\\tensorflow\\__init__.py\", line 50, in __getattr__\n",
      "    module = self._load()\n",
      "  File \"C:\\Users\\admin\\anaconda3\\lib\\site-packages\\tensorflow\\__init__.py\", line 44, in _load\n",
      "    module = _importlib.import_module(self.__name__)\n",
      "  File \"C:\\Users\\admin\\anaconda3\\lib\\importlib\\__init__.py\", line 127, in import_module\n",
      "    return _bootstrap._gcd_import(name[level:], package, level)\n",
      "  File \"C:\\Users\\admin\\anaconda3\\lib\\site-packages\\tensorflow_core\\python\\__init__.py\", line 75, in <module>\n",
      "    from tensorflow.python.framework.framework_lib import *  # pylint: disable=redefined-builtin\n",
      "  File \"C:\\Users\\admin\\anaconda3\\lib\\site-packages\\tensorflow_core\\python\\framework\\framework_lib.py\", line 25, in <module>\n",
      "    from tensorflow.python.framework.ops import Graph\n",
      "  File \"C:\\Users\\admin\\anaconda3\\lib\\site-packages\\tensorflow_core\\python\\framework\\ops.py\", line 46, in <module>\n",
      "    from tensorflow.python.framework import composite_tensor\n",
      "  File \"C:\\Users\\admin\\anaconda3\\lib\\site-packages\\tensorflow_core\\python\\framework\\composite_tensor.py\", line 27, in <module>\n",
      "    from tensorflow.python.util import nest\n",
      "  File \"C:\\Users\\admin\\anaconda3\\lib\\site-packages\\tensorflow_core\\python\\util\\nest.py\", line 40, in <module>\n",
      "    import wrapt as _wrapt\n",
      "ModuleNotFoundError: No module named 'wrapt'\n",
      "\n",
      "During handling of the above exception, another exception occurred:\n",
      "\n",
      "Traceback (most recent call last):\n",
      "  File \"C:\\Users\\admin\\anaconda3\\lib\\site-packages\\IPython\\core\\interactiveshell.py\", line 2064, in showtraceback\n",
      "    stb = value._render_traceback_()\n",
      "AttributeError: 'ModuleNotFoundError' object has no attribute '_render_traceback_'\n",
      "\n",
      "During handling of the above exception, another exception occurred:\n",
      "\n",
      "Traceback (most recent call last):\n",
      "  File \"C:\\Users\\admin\\anaconda3\\lib\\site-packages\\IPython\\core\\interactiveshell.py\", line 3364, in run_ast_nodes\n",
      "    if (await self.run_code(code, result,  async_=asy)):\n",
      "  File \"C:\\Users\\admin\\anaconda3\\lib\\site-packages\\IPython\\core\\interactiveshell.py\", line 3461, in run_code\n",
      "    self.showtraceback(running_compiled_code=True)\n",
      "  File \"C:\\Users\\admin\\anaconda3\\lib\\site-packages\\IPython\\core\\interactiveshell.py\", line 2067, in showtraceback\n",
      "    value, tb, tb_offset=tb_offset)\n",
      "  File \"C:\\Users\\admin\\anaconda3\\lib\\site-packages\\IPython\\core\\ultratb.py\", line 1368, in structured_traceback\n",
      "    self, etype, value, tb, tb_offset, number_of_lines_of_context)\n",
      "  File \"C:\\Users\\admin\\anaconda3\\lib\\site-packages\\IPython\\core\\ultratb.py\", line 1268, in structured_traceback\n",
      "    self, etype, value, tb, tb_offset, number_of_lines_of_context\n",
      "  File \"C:\\Users\\admin\\anaconda3\\lib\\site-packages\\IPython\\core\\ultratb.py\", line 1125, in structured_traceback\n",
      "    tb_offset)\n",
      "  File \"C:\\Users\\admin\\anaconda3\\lib\\site-packages\\IPython\\core\\ultratb.py\", line 1082, in format_exception_as_a_whole\n",
      "    last_unique, recursion_repeat = find_recursion(orig_etype, evalue, records)\n",
      "  File \"C:\\Users\\admin\\anaconda3\\lib\\site-packages\\IPython\\core\\ultratb.py\", line 382, in find_recursion\n",
      "    return len(records), 0\n",
      "TypeError: object of type 'NoneType' has no len()\n",
      "\n",
      "During handling of the above exception, another exception occurred:\n",
      "\n",
      "Traceback (most recent call last):\n",
      "  File \"C:\\Users\\admin\\anaconda3\\lib\\site-packages\\IPython\\core\\interactiveshell.py\", line 2064, in showtraceback\n",
      "    stb = value._render_traceback_()\n",
      "AttributeError: 'TypeError' object has no attribute '_render_traceback_'\n",
      "\n",
      "During handling of the above exception, another exception occurred:\n",
      "\n",
      "Traceback (most recent call last):\n",
      "  File \"C:\\Users\\admin\\anaconda3\\lib\\site-packages\\IPython\\core\\ultratb.py\", line 1101, in get_records\n",
      "    return _fixed_getinnerframes(etb, number_of_lines_of_context, tb_offset)\n",
      "  File \"C:\\Users\\admin\\anaconda3\\lib\\site-packages\\IPython\\core\\ultratb.py\", line 248, in wrapped\n",
      "    return f(*args, **kwargs)\n",
      "  File \"C:\\Users\\admin\\anaconda3\\lib\\site-packages\\IPython\\core\\ultratb.py\", line 281, in _fixed_getinnerframes\n",
      "    records = fix_frame_records_filenames(inspect.getinnerframes(etb, context))\n",
      "  File \"C:\\Users\\admin\\anaconda3\\lib\\inspect.py\", line 1495, in getinnerframes\n",
      "    frameinfo = (tb.tb_frame,) + getframeinfo(tb, context)\n",
      "  File \"C:\\Users\\admin\\anaconda3\\lib\\inspect.py\", line 1453, in getframeinfo\n",
      "    filename = getsourcefile(frame) or getfile(frame)\n",
      "  File \"C:\\Users\\admin\\anaconda3\\lib\\inspect.py\", line 696, in getsourcefile\n",
      "    if getattr(getmodule(object, filename), '__loader__', None) is not None:\n",
      "  File \"C:\\Users\\admin\\anaconda3\\lib\\inspect.py\", line 733, in getmodule\n",
      "    if ismodule(module) and hasattr(module, '__file__'):\n",
      "  File \"C:\\Users\\admin\\anaconda3\\lib\\site-packages\\tensorflow\\__init__.py\", line 50, in __getattr__\n",
      "    module = self._load()\n",
      "  File \"C:\\Users\\admin\\anaconda3\\lib\\site-packages\\tensorflow\\__init__.py\", line 44, in _load\n",
      "    module = _importlib.import_module(self.__name__)\n",
      "  File \"C:\\Users\\admin\\anaconda3\\lib\\importlib\\__init__.py\", line 127, in import_module\n",
      "    return _bootstrap._gcd_import(name[level:], package, level)\n",
      "  File \"<frozen importlib._bootstrap>\", line 1006, in _gcd_import\n",
      "  File \"<frozen importlib._bootstrap>\", line 983, in _find_and_load\n",
      "  File \"<frozen importlib._bootstrap>\", line 953, in _find_and_load_unlocked\n",
      "  File \"<frozen importlib._bootstrap>\", line 219, in _call_with_frames_removed\n",
      "  File \"<frozen importlib._bootstrap>\", line 1006, in _gcd_import\n",
      "  File \"<frozen importlib._bootstrap>\", line 983, in _find_and_load\n",
      "  File \"<frozen importlib._bootstrap>\", line 967, in _find_and_load_unlocked\n",
      "  File \"<frozen importlib._bootstrap>\", line 677, in _load_unlocked\n",
      "  File \"<frozen importlib._bootstrap_external>\", line 728, in exec_module\n",
      "  File \"<frozen importlib._bootstrap>\", line 219, in _call_with_frames_removed\n",
      "  File \"C:\\Users\\admin\\anaconda3\\lib\\site-packages\\tensorflow_core\\__init__.py\", line 42, in <module>\n",
      "    from . _api.v2 import audio\n",
      "  File \"C:\\Users\\admin\\anaconda3\\lib\\site-packages\\tensorflow_core\\_api\\v2\\audio\\__init__.py\", line 10, in <module>\n",
      "    from tensorflow.python.ops.gen_audio_ops import decode_wav\n",
      "  File \"C:\\Users\\admin\\anaconda3\\lib\\site-packages\\tensorflow_core\\python\\ops\\gen_audio_ops.py\", line 12, in <module>\n",
      "    from tensorflow.python.eager import execute as _execute\n",
      "  File \"C:\\Users\\admin\\anaconda3\\lib\\site-packages\\tensorflow_core\\python\\eager\\execute.py\", line 28, in <module>\n",
      "    from tensorflow.python.framework import ops\n",
      "  File \"C:\\Users\\admin\\anaconda3\\lib\\site-packages\\tensorflow_core\\python\\framework\\ops.py\", line 46, in <module>\n",
      "    from tensorflow.python.framework import composite_tensor\n",
      "  File \"C:\\Users\\admin\\anaconda3\\lib\\site-packages\\tensorflow_core\\python\\framework\\composite_tensor.py\", line 27, in <module>\n",
      "    from tensorflow.python.util import nest\n",
      "  File \"C:\\Users\\admin\\anaconda3\\lib\\site-packages\\tensorflow_core\\python\\util\\nest.py\", line 40, in <module>\n",
      "    import wrapt as _wrapt\n",
      "ModuleNotFoundError: No module named 'wrapt'\n",
      "Traceback (most recent call last):\n",
      "  File \"C:\\Users\\admin\\anaconda3\\lib\\site-packages\\IPython\\core\\interactiveshell.py\", line 3444, in run_code\n",
      "    exec(code_obj, self.user_global_ns, self.user_ns)\n",
      "  File \"C:\\Users\\admin\\AppData\\Local\\Temp/ipykernel_19960/1515776653.py\", line 6, in <module>\n",
      "    from tensorflow.keras.models import load_model\n",
      "  File \"C:\\Users\\admin\\anaconda3\\lib\\site-packages\\tensorflow\\__init__.py\", line 101, in <module>\n",
      "    from tensorflow_core import *\n",
      "  File \"C:\\Users\\admin\\anaconda3\\lib\\site-packages\\tensorflow_core\\__init__.py\", line 40, in <module>\n",
      "    from tensorflow.python.tools import module_util as _module_util\n",
      "  File \"C:\\Users\\admin\\anaconda3\\lib\\site-packages\\tensorflow\\__init__.py\", line 50, in __getattr__\n",
      "    module = self._load()\n",
      "  File \"C:\\Users\\admin\\anaconda3\\lib\\site-packages\\tensorflow\\__init__.py\", line 44, in _load\n",
      "    module = _importlib.import_module(self.__name__)\n",
      "  File \"C:\\Users\\admin\\anaconda3\\lib\\importlib\\__init__.py\", line 127, in import_module\n",
      "    return _bootstrap._gcd_import(name[level:], package, level)\n",
      "  File \"C:\\Users\\admin\\anaconda3\\lib\\site-packages\\tensorflow_core\\python\\__init__.py\", line 75, in <module>\n",
      "    from tensorflow.python.framework.framework_lib import *  # pylint: disable=redefined-builtin\n",
      "  File \"C:\\Users\\admin\\anaconda3\\lib\\site-packages\\tensorflow_core\\python\\framework\\framework_lib.py\", line 25, in <module>\n",
      "    from tensorflow.python.framework.ops import Graph\n",
      "  File \"C:\\Users\\admin\\anaconda3\\lib\\site-packages\\tensorflow_core\\python\\framework\\ops.py\", line 46, in <module>\n",
      "    from tensorflow.python.framework import composite_tensor\n",
      "  File \"C:\\Users\\admin\\anaconda3\\lib\\site-packages\\tensorflow_core\\python\\framework\\composite_tensor.py\", line 27, in <module>\n",
      "    from tensorflow.python.util import nest\n",
      "  File \"C:\\Users\\admin\\anaconda3\\lib\\site-packages\\tensorflow_core\\python\\util\\nest.py\", line 40, in <module>\n",
      "    import wrapt as _wrapt\n",
      "ModuleNotFoundError: No module named 'wrapt'\n",
      "\n",
      "During handling of the above exception, another exception occurred:\n",
      "\n",
      "Traceback (most recent call last):\n",
      "  File \"C:\\Users\\admin\\anaconda3\\lib\\site-packages\\IPython\\core\\interactiveshell.py\", line 2064, in showtraceback\n",
      "    stb = value._render_traceback_()\n",
      "AttributeError: 'ModuleNotFoundError' object has no attribute '_render_traceback_'\n",
      "\n",
      "During handling of the above exception, another exception occurred:\n",
      "\n",
      "Traceback (most recent call last):\n",
      "  File \"C:\\Users\\admin\\anaconda3\\lib\\site-packages\\IPython\\core\\interactiveshell.py\", line 3364, in run_ast_nodes\n",
      "    if (await self.run_code(code, result,  async_=asy)):\n",
      "  File \"C:\\Users\\admin\\anaconda3\\lib\\site-packages\\IPython\\core\\interactiveshell.py\", line 3461, in run_code\n",
      "    self.showtraceback(running_compiled_code=True)\n",
      "  File \"C:\\Users\\admin\\anaconda3\\lib\\site-packages\\IPython\\core\\interactiveshell.py\", line 2067, in showtraceback\n",
      "    value, tb, tb_offset=tb_offset)\n",
      "  File \"C:\\Users\\admin\\anaconda3\\lib\\site-packages\\IPython\\core\\ultratb.py\", line 1368, in structured_traceback\n",
      "    self, etype, value, tb, tb_offset, number_of_lines_of_context)\n",
      "  File \"C:\\Users\\admin\\anaconda3\\lib\\site-packages\\IPython\\core\\ultratb.py\", line 1268, in structured_traceback\n",
      "    self, etype, value, tb, tb_offset, number_of_lines_of_context\n",
      "  File \"C:\\Users\\admin\\anaconda3\\lib\\site-packages\\IPython\\core\\ultratb.py\", line 1125, in structured_traceback\n",
      "    tb_offset)\n",
      "  File \"C:\\Users\\admin\\anaconda3\\lib\\site-packages\\IPython\\core\\ultratb.py\", line 1082, in format_exception_as_a_whole\n",
      "    last_unique, recursion_repeat = find_recursion(orig_etype, evalue, records)\n",
      "  File \"C:\\Users\\admin\\anaconda3\\lib\\site-packages\\IPython\\core\\ultratb.py\", line 382, in find_recursion\n",
      "    return len(records), 0\n",
      "TypeError: object of type 'NoneType' has no len()\n",
      "\n",
      "During handling of the above exception, another exception occurred:\n",
      "\n",
      "Traceback (most recent call last):\n",
      "  File \"C:\\Users\\admin\\anaconda3\\lib\\site-packages\\IPython\\core\\interactiveshell.py\", line 2064, in showtraceback\n",
      "    stb = value._render_traceback_()\n",
      "AttributeError: 'TypeError' object has no attribute '_render_traceback_'\n",
      "\n",
      "During handling of the above exception, another exception occurred:\n",
      "\n",
      "Traceback (most recent call last):\n",
      "  File \"C:\\Users\\admin\\anaconda3\\lib\\site-packages\\IPython\\core\\interactiveshell.py\", line 2947, in _run_cell\n",
      "    return runner(coro)\n",
      "  File \"C:\\Users\\admin\\anaconda3\\lib\\site-packages\\IPython\\core\\async_helpers.py\", line 68, in _pseudo_sync_runner\n",
      "    coro.send(None)\n",
      "  File \"C:\\Users\\admin\\anaconda3\\lib\\site-packages\\IPython\\core\\interactiveshell.py\", line 3173, in run_cell_async\n",
      "    interactivity=interactivity, compiler=compiler, result=result)\n",
      "  File \"C:\\Users\\admin\\anaconda3\\lib\\site-packages\\IPython\\core\\interactiveshell.py\", line 3383, in run_ast_nodes\n",
      "    self.showtraceback()\n",
      "  File \"C:\\Users\\admin\\anaconda3\\lib\\site-packages\\IPython\\core\\interactiveshell.py\", line 2067, in showtraceback\n",
      "    value, tb, tb_offset=tb_offset)\n",
      "  File \"C:\\Users\\admin\\anaconda3\\lib\\site-packages\\IPython\\core\\ultratb.py\", line 1368, in structured_traceback\n",
      "    self, etype, value, tb, tb_offset, number_of_lines_of_context)\n",
      "  File \"C:\\Users\\admin\\anaconda3\\lib\\site-packages\\IPython\\core\\ultratb.py\", line 1268, in structured_traceback\n",
      "    self, etype, value, tb, tb_offset, number_of_lines_of_context\n",
      "  File \"C:\\Users\\admin\\anaconda3\\lib\\site-packages\\IPython\\core\\ultratb.py\", line 1143, in structured_traceback\n",
      "    chained_exceptions_tb_offset)\n",
      "  File \"C:\\Users\\admin\\anaconda3\\lib\\site-packages\\IPython\\core\\ultratb.py\", line 1082, in format_exception_as_a_whole\n",
      "    last_unique, recursion_repeat = find_recursion(orig_etype, evalue, records)\n",
      "  File \"C:\\Users\\admin\\anaconda3\\lib\\site-packages\\IPython\\core\\ultratb.py\", line 382, in find_recursion\n",
      "    return len(records), 0\n",
      "TypeError: object of type 'NoneType' has no len()\n",
      "\n",
      "During handling of the above exception, another exception occurred:\n",
      "\n",
      "Traceback (most recent call last):\n",
      "  File \"C:\\Users\\admin\\anaconda3\\lib\\site-packages\\IPython\\core\\interactiveshell.py\", line 2064, in showtraceback\n",
      "    stb = value._render_traceback_()\n",
      "AttributeError: 'TypeError' object has no attribute '_render_traceback_'\n",
      "\n",
      "During handling of the above exception, another exception occurred:\n",
      "\n",
      "Traceback (most recent call last):\n",
      "  File \"C:\\Users\\admin\\anaconda3\\lib\\site-packages\\IPython\\core\\ultratb.py\", line 1101, in get_records\n",
      "    return _fixed_getinnerframes(etb, number_of_lines_of_context, tb_offset)\n",
      "  File \"C:\\Users\\admin\\anaconda3\\lib\\site-packages\\IPython\\core\\ultratb.py\", line 248, in wrapped\n",
      "    return f(*args, **kwargs)\n",
      "  File \"C:\\Users\\admin\\anaconda3\\lib\\site-packages\\IPython\\core\\ultratb.py\", line 281, in _fixed_getinnerframes\n",
      "    records = fix_frame_records_filenames(inspect.getinnerframes(etb, context))\n",
      "  File \"C:\\Users\\admin\\anaconda3\\lib\\inspect.py\", line 1495, in getinnerframes\n",
      "    frameinfo = (tb.tb_frame,) + getframeinfo(tb, context)\n",
      "  File \"C:\\Users\\admin\\anaconda3\\lib\\inspect.py\", line 1453, in getframeinfo\n",
      "    filename = getsourcefile(frame) or getfile(frame)\n",
      "  File \"C:\\Users\\admin\\anaconda3\\lib\\inspect.py\", line 696, in getsourcefile\n",
      "    if getattr(getmodule(object, filename), '__loader__', None) is not None:\n",
      "  File \"C:\\Users\\admin\\anaconda3\\lib\\inspect.py\", line 733, in getmodule\n",
      "    if ismodule(module) and hasattr(module, '__file__'):\n",
      "  File \"C:\\Users\\admin\\anaconda3\\lib\\site-packages\\tensorflow\\__init__.py\", line 50, in __getattr__\n",
      "    module = self._load()\n",
      "  File \"C:\\Users\\admin\\anaconda3\\lib\\site-packages\\tensorflow\\__init__.py\", line 44, in _load\n",
      "    module = _importlib.import_module(self.__name__)\n",
      "  File \"C:\\Users\\admin\\anaconda3\\lib\\importlib\\__init__.py\", line 127, in import_module\n",
      "    return _bootstrap._gcd_import(name[level:], package, level)\n",
      "  File \"<frozen importlib._bootstrap>\", line 1006, in _gcd_import\n",
      "  File \"<frozen importlib._bootstrap>\", line 983, in _find_and_load\n",
      "  File \"<frozen importlib._bootstrap>\", line 953, in _find_and_load_unlocked\n",
      "  File \"<frozen importlib._bootstrap>\", line 219, in _call_with_frames_removed\n",
      "  File \"<frozen importlib._bootstrap>\", line 1006, in _gcd_import\n",
      "  File \"<frozen importlib._bootstrap>\", line 983, in _find_and_load\n",
      "  File \"<frozen importlib._bootstrap>\", line 967, in _find_and_load_unlocked\n",
      "  File \"<frozen importlib._bootstrap>\", line 677, in _load_unlocked\n",
      "  File \"<frozen importlib._bootstrap_external>\", line 728, in exec_module\n",
      "  File \"<frozen importlib._bootstrap>\", line 219, in _call_with_frames_removed\n",
      "  File \"C:\\Users\\admin\\anaconda3\\lib\\site-packages\\tensorflow_core\\__init__.py\", line 42, in <module>\n",
      "    from . _api.v2 import audio\n",
      "  File \"C:\\Users\\admin\\anaconda3\\lib\\site-packages\\tensorflow_core\\_api\\v2\\audio\\__init__.py\", line 10, in <module>\n",
      "    from tensorflow.python.ops.gen_audio_ops import decode_wav\n",
      "  File \"C:\\Users\\admin\\anaconda3\\lib\\site-packages\\tensorflow_core\\python\\ops\\gen_audio_ops.py\", line 12, in <module>\n",
      "    from tensorflow.python.eager import execute as _execute\n",
      "  File \"C:\\Users\\admin\\anaconda3\\lib\\site-packages\\tensorflow_core\\python\\eager\\execute.py\", line 28, in <module>\n",
      "    from tensorflow.python.framework import ops\n",
      "  File \"C:\\Users\\admin\\anaconda3\\lib\\site-packages\\tensorflow_core\\python\\framework\\ops.py\", line 46, in <module>\n",
      "    from tensorflow.python.framework import composite_tensor\n",
      "  File \"C:\\Users\\admin\\anaconda3\\lib\\site-packages\\tensorflow_core\\python\\framework\\composite_tensor.py\", line 27, in <module>\n",
      "    from tensorflow.python.util import nest\n",
      "  File \"C:\\Users\\admin\\anaconda3\\lib\\site-packages\\tensorflow_core\\python\\util\\nest.py\", line 40, in <module>\n",
      "    import wrapt as _wrapt\n",
      "ModuleNotFoundError: No module named 'wrapt'\n"
     ]
    }
   ],
   "source": [
    "import os\n",
    "import platform\n",
    "from IPython.display import clear_output\n",
    "from IPython.display import HTML\n",
    "from base64 import b64encode\n",
    "from tensorflow.keras.models import load_model\n",
    "from collections import deque\n",
    "import matplotlib.pyplot as plt\n",
    "import numpy as np\n",
    "import argparse\n",
    "import pickle\n",
    "import cv2\n",
    "import warnings\n",
    "warnings.filterwarnings(\"ignore\")"
   ]
  },
  {
   "cell_type": "markdown",
   "id": "prompt-heaven",
   "metadata": {
    "id": "prompt-heaven",
    "papermill": {
     "duration": 3.740652,
     "end_time": "2021-05-08T02:30:05.041672",
     "exception": false,
     "start_time": "2021-05-08T02:30:01.301020",
     "status": "completed"
    },
    "tags": []
   },
   "source": [
    "## **Testing**"
   ]
  },
  {
   "cell_type": "code",
   "execution_count": 16,
   "id": "natural-convertible",
   "metadata": {
    "colab": {
     "base_uri": "https://localhost:8080/",
     "height": 423,
     "output_embedded_package_id": "1ASpoChqkuoe8v2Y4amFw4XaERDba5oV2"
    },
    "execution": {
     "iopub.execute_input": "2021-05-08T02:30:28.474810Z",
     "iopub.status.busy": "2021-05-08T02:30:28.473990Z",
     "iopub.status.idle": "2021-05-08T02:30:28.557317Z",
     "shell.execute_reply": "2021-05-08T02:30:28.557834Z"
    },
    "executionInfo": {
     "elapsed": 5531,
     "status": "ok",
     "timestamp": 1620713371182,
     "user": {
      "displayName": "HHK Mmk",
      "photoUrl": "https://lh3.googleusercontent.com/a-/AOh14Gj9u9VsU8JrrRLuhjNo1_RvBxXqIZIwiILnsBRR=s64",
      "userId": "07317510250984342733"
     },
     "user_tz": -540
    },
    "id": "natural-convertible",
    "outputId": "7e62106a-8ff4-46b9-baf9-dc15adf4c9c4",
    "papermill": {
     "duration": 3.97684,
     "end_time": "2021-05-08T02:30:28.557990",
     "exception": false,
     "start_time": "2021-05-08T02:30:24.581150",
     "status": "completed"
    },
    "tags": []
   },
   "outputs": [
    {
     "data": {
      "text/plain": [
       "Output hidden; open in https://colab.research.google.com to view."
      ]
     },
     "metadata": {},
     "output_type": "display_data"
    }
   ],
   "source": [
    "xml = 'haarcascades/haarcascade_frontalface_default.xml'\n",
    "face_cascade = cv2.CascadeClassifier(xml)\n",
    "\n",
    "cap = cv2.VideoCapture(0) # 노트북 웹캠을 카메라로 사용\n",
    "cap.set(3,640) # 너비\n",
    "cap.set(4,480) # 높이\n",
    "\n",
    "flag =0\n",
    "model = load_model('DenseNet121.h5')\n",
    "while(True):\n",
    "    ret, frame = cap.read()\n",
    "    frame = cv2.flip(frame, 1) # 좌우 대칭\n",
    "    img = cv2.cvtColor(frame, cv2.COLOR_BGR2RGB)\n",
    "    output = cv2.resize(img, (512, 360)).copy()\n",
    "    processed_img = cv2.resize(img,(128,128))\n",
    "    processed_img = np.reshape(processed_img,[1,128,128,3])\n",
    "    processed_img = processed_img/255.0\n",
    "\n",
    "    prediction = model.predict(processed_img)[0][0] # 사진의 결과값 에측\n",
    "\n",
    "\n",
    "    # 해당 프레임마다 모델의 예측 결과를 텍스트로 채워주기\n",
    "    text_color = (0, 255, 0) # default : green\n",
    "\n",
    "    if prediction > 0.50 : # mask prob\n",
    "        text_color = (0, 0, 255) # red\n",
    "        label = 'wearing a mask'\n",
    "        flag = 0\n",
    "    else:\n",
    "        label = 'Not wearing a mask'\n",
    "        flag = flag+1\n",
    "    if flag >= 10:\n",
    "        text = \"State : warning \"\n",
    "    else:\n",
    "        text = \"State : {:8} ({:3.2f}%)\".format(label,prediction*100)\n",
    "    FONT = cv2.FONT_HERSHEY_SIMPLEX \n",
    "\n",
    "    cv2.putText(output, text, (35, 50), FONT,1.25, text_color, 3) \n",
    "    output = cv2.rectangle(output, (35, 80), (35+int(preds[0])*5,80+20), text_color,-1)\n",
    "\n",
    "    if writer is None:\n",
    "        fourcc = cv2.VideoWriter_fourcc(*\"MJPG\")\n",
    "        writer = cv2.VideoWriter(args[\"output\"], fourcc, 30,(W, H), True)\n",
    "    writer.write(output)\n",
    "\n",
    "    # 프레임 이미지를 출력하기\n",
    "    cv2_imshow(output)\n",
    "    key = cv2.waitKey(1) & 0xFF\n",
    "    if key == ord(\"q\"):\n",
    "        break"
   ]
  }
 ],
 "metadata": {
  "colab": {
   "collapsed_sections": [],
   "name": "violence_classification_v1.ipynb",
   "provenance": []
  },
  "kernelspec": {
   "display_name": "Python 3 (ipykernel)",
   "language": "python",
   "name": "python3"
  },
  "language_info": {
   "codemirror_mode": {
    "name": "ipython",
    "version": 3
   },
   "file_extension": ".py",
   "mimetype": "text/x-python",
   "name": "python",
   "nbconvert_exporter": "python",
   "pygments_lexer": "ipython3",
   "version": "3.7.0"
  },
  "papermill": {
   "default_parameters": {},
   "duration": 1541.952186,
   "end_time": "2021-05-08T02:32:43.321079",
   "environment_variables": {},
   "exception": null,
   "input_path": "__notebook__.ipynb",
   "output_path": "__notebook__.ipynb",
   "parameters": {},
   "start_time": "2021-05-08T02:07:01.368893",
   "version": "2.3.3"
  }
 },
 "nbformat": 4,
 "nbformat_minor": 5
}
